Workbook

Sheet Notizblatt
A1: Stückliste Notizblatt
A2: Lfd. Nr. | B2: Stück- zahl | C2: Ein- heit | D2: Benennung | E2: Referenzkennzeichen | F2: Lieferant | G2: Bestellnummer | H2: MCd | I2: Preis/EH | J2: VE | K2: Bemerkung
A3: 1 | B3: 40 | C3: STK | D3: Choc V1 Switches | E3: SWL1-20, SWR1-20 | F3: keeb.supply | I3: =9.5/10 -> 0.95 | J3: 10 | K3: Ambients Silent Linear Twilight
A4: 2 | B4: 40 | C4: STK | D4: Kailh-Choc 1350 Hot Swap Sockets | E4: SWL1-20, SWR1-20 | F4: keeb.supply | I4: =2.2/10 -> 0.22 | J4: 10 | K4: Choc Kailh hotswap sockets
A5: 3 | B5: 40 | C5: STK | D5: 1N4148 | E5: DL1-20, DR1-20 | F5: s-grundner | G5: 1N 4148 | I5: 0 | J5: 1 | K5: THT version
A6: 4 | B6: 2 | C6: STK | D6: Reset Button | E6: RSW1,2 | F6: keeb.supply | G6: SKHLLCA010 | I6: 0.6 | J6: 1 | K6: Alps
A7: 5 | B7: 1 | C7: STK | D7: PCB | F7: l-langegger | I7: 0 | J7: 5 | K7: PCB-Way via Sammelbestellung
A8: 6 | B8: 2 | C8: STK | D8: LiPo Akku 3.7V | F8: reichelt.de | G8: AKKU 30851 | I8: 5.3 | J8: 1 | K8: 140mAh, L=24.4mm, B=13.1mm, H=6.1mm
A9: 7 | B9: 3 | C9: STK | D9: Seeed Studio XIAO nRF52840 | E9: U1,2 | F9: reichelt.de | G9: XIAO NRF52840 | I9: 12.8 | J9: 1
A10: 8 | B10: 2 | C10: STK | D10: SPST Power Switch | E10: PSW1,2 | F10: keeb.supply | G10: MSK-12C02 | I10: 0.8 | J10: 1 | K10: Switch Mini 7 Pin 2 Slide Positions
A11: 9 | B11: 4 | C11: STK | D11: Gummi Füße | F11: amazon.de | I11: =3.99/100 -> 0.0399 | J11: 100 | K11: Round Silicone Rubber Feet
A12: 10 | B12: 4 | C12: STK | D12: Brass Standoffs
A13: 11 | B13: 1 | C13: STK | D13: Shipping Reichelt | I13: 5.95 | J13: 1
A14: 12 | B14: 1 | C14: STK | D14: Shipping JLC | J14: 1
A114: Nach dieser Linie dürfen keine Daten mehr eingegeben werden

Sheet Eingabe
A1: Jahrgang: | G1: Toleranz: | K1: Dokumentart: | L1: Stückliste | M1: Sachnummer, Dateiname:
A2: Katalognummer: | G2: Werkstoff: | I2: FR4 | K2: Datum: | L2: =TODAY() -> 45824 | M2: Stückliste:
A3: Vorname Nachname: | E3: Simon Grundner | G3: Geprüft : | K3: Version: | L3: 1.0 | M3: Materialkalkulation:
A4: Kurzzeichen: | E4: GruS | G4: Betreuer: | K4: Revision: | L4: 1 | M4: Einheiten zur Bestellung: | O4: 1
A5: Benennung (Projekt) / Version: | E5: TOTEM - Bluetooth | G5: Freigabe. | K5: Dokumentenstatus: | L5: Fertigung | M5: Ausbildungsrichtung:
A6: Benennung (Projekt) Zeile 2: | E6: 40 Key Split Ergomech KB | G6: Sprache: | I6: DE | K6: Maßstab: | L6: ohne | M6: Technische Informatik
A7: Lfd. Nr. | B7: Stück- zahl | C7: Ein- heit | D7: Benennung | E7: Referenzkennzeichen | F7: Lieferant | G7: Bestellnummer | H7: MCd | I7: Preis/EH | J7: VE | K7: Bemerkung | L7: ="Preisvorschau "&ROUNDUP((SUM(L8:L130)+(SUM(L8:L130)*0.1)+(SUM(L8:L130)+(SUM(L8:L130)*0.1))*0.2)/$O$4,2)&" €/STK" -> Preisvorschau 135.42 €/STK | M7: =$O$4&" "&"EH inkl. 10% GK = "&ROUNDUP(SUM(L8:L130)+(SUM(L8:L130)*0.1),2)&" €"&" zuzgl. 20% MwSt."&" = "&ROUNDUP((SUM(L8:L130)+(SUM(L8:L130)*0.1)+(SUM(L8:L130)+(SUM(L8:L130)*0.1))*0.2),2)&" €"&" Bestellnummer"&" "&"Bestellmenge "&" "&"Bestelltextkontrolle - "&"Ben. Ref.KZ"&" - keine Feldlängenkontrolle " -> 1 EH inkl. 10% GK = 112.85 € zuzgl. 20% MwSt. = 135.42 € Bestellnummer Bestellmenge Bestelltextkontrolle - Ben. Ref.KZ - keine Feldlängenkontrolle
A8: 1 | B8: 40 | C8: STK | D8: Choc V1 Switches | E8: SWL1-20, SWR1-20 | F8: keeb.supply | I8: 0.95 | J8: 10 | K8: Ambients Silent Linear Twilight | L8: =IF(I8="","",IF($L$6="mit",IF(B8*I8*$O$4=0,"",B8*I8*$O$4),IF(B8*I8*$O$4=0,"",INT(CEILING(B8*$O$4,J8))*I8))) -> 38 | M8: =IF(L8="","",G8) -> 0 | N8: =IF(L8="","",IF($L$6="mit",IF(B8*$O$4=0,"",B8*$O$4&" "&C8&" "),IF(B8*$O$4=0,"",INT(CEILING(B8*$O$4,J8))&" "&C8&" "))) -> 40 STK | O8: =IF(L8="","",IF($O$4="","",D8&" "&E8)) -> Choc V1 Switches SWL1-20, SWR1-20
A9: 2 | B9: 40 | C9: STK | D9: Kailh-Choc 1350 Hot Swap Sockets | E9: SWL1-20, SWR1-20 | F9: keeb.supply | I9: 0.22 | J9: 10 | K9: Choc Kailh hotswap sockets | L9: =IF(I9="","",IF($L$6="mit",IF(B9*I9*$O$4=0,"",B9*I9*$O$4),IF(B9*I9*$O$4=0,"",INT(CEILING(B9*$O$4,J9))*I9))) -> 8.8 | M9: =IF(L9="","",G9) -> 0 | N9: =IF(L9="","",IF($L$6="mit",IF(B9*$O$4=0,"",B9*$O$4&" "&C9&" "),IF(B9*$O$4=0,"",INT(CEILING(B9*$O$4,J9))&" "&C9&" "))) -> 40 STK | O9: =IF(L9="","",IF($O$4="","",D9&" "&E9)) -> Kailh-Choc 1350 Hot Swap Sockets SWL1-20, SWR1-20
A10: 3 | B10: 40 | C10: STK | D10: 1N4148 | E10: DL1-20, DR1-20 | F10: s-grundner | G10: 1N 4148 | I10: 0 | J10: 1 | K10: THT version | L10: =IF(I10="","",IF($L$6="mit",IF(B10*I10*$O$4=0,"",B10*I10*$O$4),IF(B10*I10*$O$4=0,"",INT(CEILING(B10*$O$4,J10))*I10))) | M10: =IF(L10="","",G10) | N10: =IF(L10="","",IF($L$6="mit",IF(B10*$O$4=0,"",B10*$O$4&" "&C10&" "),IF(B10*$O$4=0,"",INT(CEILING(B10*$O$4,J10))&" "&C10&" "))) | O10: =IF(L10="","",IF($O$4="","",D10&" "&E10))
A11: 4 | B11: 2 | C11: STK | D11: Reset Button | E11: RSW1,2 | F11: keeb.supply | G11: SKHLLCA010 | I11: 0.6 | J11: 1 | K11: Alps | L11: =IF(I11="","",IF($L$6="mit",IF(B11*I11*$O$4=0,"",B11*I11*$O$4),IF(B11*I11*$O$4=0,"",INT(CEILING(B11*$O$4,J11))*I11))) -> 1.2 | M11: =IF(L11="","",G11) -> SKHLLCA010 | N11: =IF(L11="","",IF($L$6="mit",IF(B11*$O$4=0,"",B11*$O$4&" "&C11&" "),IF(B11*$O$4=0,"",INT(CEILING(B11*$O$4,J11))&" "&C11&" "))) -> 2 STK | O11: =IF(L11="","",IF($O$4="","",D11&" "&E11)) -> Reset Button RSW1,2
A12: 5 | B12: 1 | C12: STK | D12: PCB | F12: l-langegger | I12: 0 | J12: 5 | K12: PCB-Way via Sammelbestellung | L12: =IF(I12="","",IF($L$6="mit",IF(B12*I12*$O$4=0,"",B12*I12*$O$4),IF(B12*I12*$O$4=0,"",INT(CEILING(B12*$O$4,J12))*I12))) | M12: =IF(L12="","",G12) | N12: =IF(L12="","",IF($L$6="mit",IF(B12*$O$4=0,"",B12*$O$4&" "&C12&" "),IF(B12*$O$4=0,"",INT(CEILING(B12*$O$4,J12))&" "&C12&" "))) | O12: =IF(L12="","",IF($O$4="","",D12&" "&E12))
A13: 6 | B13: 2 | C13: STK | D13: LiPo Akku 3.7V | F13: reichelt.de | G13: AKKU 30851 | I13: 5.3 | J13: 1 | K13: 140mAh, L=24.4mm, B=13.1mm, H=6.1mm | L13: =IF(I13="","",IF($L$6="mit",IF(B13*I13*$O$4=0,"",B13*I13*$O$4),IF(B13*I13*$O$4=0,"",INT(CEILING(B13*$O$4,J13))*I13))) -> 10.6 | M13: =IF(L13="","",G13) -> AKKU 30851 | N13: =IF(L13="","",IF($L$6="mit",IF(B13*$O$4=0,"",B13*$O$4&" "&C13&" "),IF(B13*$O$4=0,"",INT(CEILING(B13*$O$4,J13))&" "&C13&" "))) -> 2 STK | O13: =IF(L13="","",IF($O$4="","",D13&" "&E13)) -> LiPo Akku 3.7V
A14: 7 | B14: 3 | C14: STK | D14: Seeed Studio XIAO nRF52840 | E14: U1,2 | F14: reichelt.de | G14: XIAO NRF52840 | I14: 12.8 | J14: 1 | L14: =IF(I14="","",IF($L$6="mit",IF(B14*I14*$O$4=0,"",B14*I14*$O$4),IF(B14*I14*$O$4=0,"",INT(CEILING(B14*$O$4,J14))*I14))) -> 38.4 | M14: =IF(L14="","",G14) -> XIAO NRF52840 | N14: =IF(L14="","",IF($L$6="mit",IF(B14*$O$4=0,"",B14*$O$4&" "&C14&" "),IF(B14*$O$4=0,"",INT(CEILING(B14*$O$4,J14))&" "&C14&" "))) -> 3 STK | O14: =IF(L14="","",IF($O$4="","",D14&" "&E14)) -> Seeed Studio XIAO nRF52840 U1,2
A15: 8 | B15: 2 | C15: STK | D15: SPST Power Switch | E15: PSW1,2 | F15: keeb.supply | G15: MSK-12C02 | I15: 0.8 | J15: 1 | K15: Switch Mini 7 Pin 2 Slide Positions | L15: =IF(I15="","",IF($L$6="mit",IF(B15*I15*$O$4=0,"",B15*I15*$O$4),IF(B15*I15*$O$4=0,"",INT(CEILING(B15*$O$4,J15))*I15))) -> 1.6 | M15: =IF(L15="","",G15) -> MSK-12C02 | N15: =IF(L15="","",IF($L$6="mit",IF(B15*$O$4=0,"",B15*$O$4&" "&C15&" "),IF(B15*$O$4=0,"",INT(CEILING(B15*$O$4,J15))&" "&C15&" "))) -> 2 STK | O15: =IF(L15="","",IF($O$4="","",D15&" "&E15)) -> SPST Power Switch PSW1,2
A16: 9 | B16: 4 | C16: STK | D16: Gummi Füße | F16: amazon.de | I16: 0.0399 | J16: 100 | K16: Round Silicone Rubber Feet | L16: =IF(I16="","",IF($L$6="mit",IF(B16*I16*$O$4=0,"",B16*I16*$O$4),IF(B16*I16*$O$4=0,"",INT(CEILING(B16*$O$4,J16))*I16))) -> 3.99 | M16: =IF(L16="","",G16) -> 0 | N16: =IF(L16="","",IF($L$6="mit",IF(B16*$O$4=0,"",B16*$O$4&" "&C16&" "),IF(B16*$O$4=0,"",INT(CEILING(B16*$O$4,J16))&" "&C16&" "))) -> 100 STK | O16: =IF(L16="","",IF($O$4="","",D16&" "&E16)) -> Gummi Füße
A17: 1 | L17: =IF(I17="","",IF($L$6="mit",IF(B17*I17*$O$4=0,"",B17*I17*$O$4),IF(B17*I17*$O$4=0,"",INT(CEILING(B17*$O$4,J17))*I17))) | M17: =IF(L17="","",G17) | N17: =IF(L17="","",IF($L$6="mit",IF(B17*$O$4=0,"",B17*$O$4&" "&C17&" "),IF(B17*$O$4=0,"",INT(CEILING(B17*$O$4,J17))&" "&C17&" "))) | O17: =IF(L17="","",IF($O$4="","",D17&" "&E17))
A18: 11 | L18: =IF(I18="","",IF($L$6="mit",IF(B18*I18*$O$4=0,"",B18*I18*$O$4),IF(B18*I18*$O$4=0,"",INT(CEILING(B18*$O$4,J18))*I18))) | M18: =IF(L18="","",G18) | N18: =IF(L18="","",IF($L$6="mit",IF(B18*$O$4=0,"",B18*$O$4&" "&C18&" "),IF(B18*$O$4=0,"",INT(CEILING(B18*$O$4,J18))&" "&C18&" "))) | O18: =IF(L18="","",IF($O$4="","",D18&" "&E18))
A19: 12 | L19: =IF(I19="","",IF($L$6="mit",IF(B19*I19*$O$4=0,"",B19*I19*$O$4),IF(B19*I19*$O$4=0,"",INT(CEILING(B19*$O$4,J19))*I19))) | M19: =IF(L19="","",G19) | N19: =IF(L19="","",IF($L$6="mit",IF(B19*$O$4=0,"",B19*$O$4&" "&C19&" "),IF(B19*$O$4=0,"",INT(CEILING(B19*$O$4,J19))&" "&C19&" "))) | O19: =IF(L19="","",IF($O$4="","",D19&" "&E19))
A20: 13 | L20: =IF(I20="","",IF($L$6="mit",IF(B20*I20*$O$4=0,"",B20*I20*$O$4),IF(B20*I20*$O$4=0,"",INT(CEILING(B20*$O$4,J20))*I20))) | M20: =IF(L20="","",G20) | N20: =IF(L20="","",IF($L$6="mit",IF(B20*$O$4=0,"",B20*$O$4&" "&C20&" "),IF(B20*$O$4=0,"",INT(CEILING(B20*$O$4,J20))&" "&C20&" "))) | O20: =IF(L20="","",IF($O$4="","",D20&" "&E20))
A21: 14 | L21: =IF(I21="","",IF($L$6="mit",IF(B21*I21*$O$4=0,"",B21*I21*$O$4),IF(B21*I21*$O$4=0,"",INT(CEILING(B21*$O$4,J21))*I21))) | M21: =IF(L21="","",G21) | N21: =IF(L21="","",IF($L$6="mit",IF(B21*$O$4=0,"",B21*$O$4&" "&C21&" "),IF(B21*$O$4=0,"",INT(CEILING(B21*$O$4,J21))&" "&C21&" "))) | O21: =IF(L21="","",IF($O$4="","",D21&" "&E21))
A22: 15 | L22: =IF(I22="","",IF($L$6="mit",IF(B22*I22*$O$4=0,"",B22*I22*$O$4),IF(B22*I22*$O$4=0,"",INT(CEILING(B22*$O$4,J22))*I22))) | M22: =IF(L22="","",G22) | N22: =IF(L22="","",IF($L$6="mit",IF(B22*$O$4=0,"",B22*$O$4&" "&C22&" "),IF(B22*$O$4=0,"",INT(CEILING(B22*$O$4,J22))&" "&C22&" "))) | O22: =IF(L22="","",IF($O$4="","",D22&" "&E22))
A23: 16 | L23: =IF(I23="","",IF($L$6="mit",IF(B23*I23*$O$4=0,"",B23*I23*$O$4),IF(B23*I23*$O$4=0,"",INT(CEILING(B23*$O$4,J23))*I23))) | M23: =IF(L23="","",G23) | N23: =IF(L23="","",IF($L$6="mit",IF(B23*$O$4=0,"",B23*$O$4&" "&C23&" "),IF(B23*$O$4=0,"",INT(CEILING(B23*$O$4,J23))&" "&C23&" "))) | O23: =IF(L23="","",IF($O$4="","",D23&" "&E23))
A24: 17 | L24: =IF(I24="","",IF($L$6="mit",IF(B24*I24*$O$4=0,"",B24*I24*$O$4),IF(B24*I24*$O$4=0,"",INT(CEILING(B24*$O$4,J24))*I24))) | M24: =IF(L24="","",G24) | N24: =IF(L24="","",IF($L$6="mit",IF(B24*$O$4=0,"",B24*$O$4&" "&C24&" "),IF(B24*$O$4=0,"",INT(CEILING(B24*$O$4,J24))&" "&C24&" "))) | O24: =IF(L24="","",IF($O$4="","",D24&" "&E24))
A25: 18 | L25: =IF(I25="","",IF($L$6="mit",IF(B25*I25*$O$4=0,"",B25*I25*$O$4),IF(B25*I25*$O$4=0,"",INT(CEILING(B25*$O$4,J25))*I25))) | M25: =IF(L25="","",G25) | N25: =IF(L25="","",IF($L$6="mit",IF(B25*$O$4=0,"",B25*$O$4&" "&C25&" "),IF(B25*$O$4=0,"",INT(CEILING(B25*$O$4,J25))&" "&C25&" "))) | O25: =IF(L25="","",IF($O$4="","",D25&" "&E25))
A26: 19 | L26: =IF(I26="","",IF($L$6="mit",IF(B26*I26*$O$4=0,"",B26*I26*$O$4),IF(B26*I26*$O$4=0,"",INT(CEILING(B26*$O$4,J26))*I26))) | M26: =IF(L26="","",G26) | N26: =IF(L26="","",IF($L$6="mit",IF(B26*$O$4=0,"",B26*$O$4&" "&C26&" "),IF(B26*$O$4=0,"",INT(CEILING(B26*$O$4,J26))&" "&C26&" "))) | O26: =IF(L26="","",IF($O$4="","",D26&" "&E26))
A27: 20 | L27: =IF(I27="","",IF($L$6="mit",IF(B27*I27*$O$4=0,"",B27*I27*$O$4),IF(B27*I27*$O$4=0,"",INT(CEILING(B27*$O$4,J27))*I27))) | M27: =IF(L27="","",G27) | N27: =IF(L27="","",IF($L$6="mit",IF(B27*$O$4=0,"",B27*$O$4&" "&C27&" "),IF(B27*$O$4=0,"",INT(CEILING(B27*$O$4,J27))&" "&C27&" "))) | O27: =IF(L27="","",IF($O$4="","",D27&" "&E27))
A28: 21 | L28: =IF(I28="","",IF($L$6="mit",IF(B28*I28*$O$4=0,"",B28*I28*$O$4),IF(B28*I28*$O$4=0,"",INT(CEILING(B28*$O$4,J28))*I28))) | M28: =IF(L28="","",G28) | N28: =IF(L28="","",IF($L$6="mit",IF(B28*$O$4=0,"",B28*$O$4&" "&C28&" "),IF(B28*$O$4=0,"",INT(CEILING(B28*$O$4,J28))&" "&C28&" "))) | O28: =IF(L28="","",IF($O$4="","",D28&" "&E28))
... A38: 31 | L38: =IF(I38="","",IF($L$6="mit",IF(B38*I38*$O$4=0,"",B38*I38*$O$4),IF(B38*I38*$O$4=0,"",INT(CEILING(B38*$O$4,J38))*I38))) | M38: =IF(L38="","",G38) | N38: =IF(L38="","",IF($L$6="mit",IF(B38*$O$4=0,"",B38*$O$4&" "&C38&" "),IF(B38*$O$4=0,"",INT(CEILING(B38*$O$4,J38))&" "&C38&" "))) | O38: =IF(L38="","",IF($O$4="","",D38&" "&E38))
L39: =IF(I39="","",IF($L$6="mit",IF(B39*I39*$O$4=0,"",B39*I39*$O$4),IF(B39*I39*$O$4=0,"",INT(CEILING(B39*$O$4,J39))*I39))) | M39: =IF(L39="","",G39) | N39: =IF(L39="","",IF($L$6="mit",IF(B39*$O$4=0,"",B39*$O$4&" "&C39&" "),IF(B39*$O$4=0,"",INT(CEILING(B39*$O$4,J39))&" "&C39&" "))) | O39: =IF(L39="","",IF($O$4="","",D39&" "&E39))
L40: =IF(I40="","",IF($L$6="mit",IF(B40*I40*$O$4=0,"",B40*I40*$O$4),IF(B40*I40*$O$4=0,"",INT(CEILING(B40*$O$4,J40))*I40))) | M40: =IF(L40="","",G40) | N40: =IF(L40="","",IF($L$6="mit",IF(B40*$O$4=0,"",B40*$O$4&" "&C40&" "),IF(B40*$O$4=0,"",INT(CEILING(B40*$O$4,J40))&" "&C40&" "))) | O40: =IF(L40="","",IF($O$4="","",D40&" "&E40))
L41: =IF(I41="","",IF($L$6="mit",IF(B41*I41*$O$4=0,"",B41*I41*$O$4),IF(B41*I41*$O$4=0,"",INT(CEILING(B41*$O$4,J41))*I41))) | M41: =IF(L41="","",G41) | N41: =IF(L41="","",IF($L$6="mit",IF(B41*$O$4=0,"",B41*$O$4&" "&C41&" "),IF(B41*$O$4=0,"",INT(CEILING(B41*$O$4,J41))&" "&C41&" "))) | O41: =IF(L41="","",IF($O$4="","",D41&" "&E41))
L42: =IF(I42="","",IF($L$6="mit",IF(B42*I42*$O$4=0,"",B42*I42*$O$4),IF(B42*I42*$O$4=0,"",INT(CEILING(B42*$O$4,J42))*I42))) | M42: =IF(L42="","",G42) | N42: =IF(L42="","",IF($L$6="mit",IF(B42*$O$4=0,"",B42*$O$4&" "&C42&" "),IF(B42*$O$4=0,"",INT(CEILING(B42*$O$4,J42))&" "&C42&" "))) | O42: =IF(L42="","",IF($O$4="","",D42&" "&E42))
L43: =IF(I43="","",IF($L$6="mit",IF(B43*I43*$O$4=0,"",B43*I43*$O$4),IF(B43*I43*$O$4=0,"",INT(CEILING(B43*$O$4,J43))*I43))) | M43: =IF(L43="","",G43) | N43: =IF(L43="","",IF($L$6="mit",IF(B43*$O$4=0,"",B43*$O$4&" "&C43&" "),IF(B43*$O$4=0,"",INT(CEILING(B43*$O$4,J43))&" "&C43&" "))) | O43: =IF(L43="","",IF($O$4="","",D43&" "&E43))
L44: =IF(I44="","",IF($L$6="mit",IF(B44*I44*$O$4=0,"",B44*I44*$O$4),IF(B44*I44*$O$4=0,"",INT(CEILING(B44*$O$4,J44))*I44))) | M44: =IF(L44="","",G44) | N44: =IF(L44="","",IF($L$6="mit",IF(B44*$O$4=0,"",B44*$O$4&" "&C44&" "),IF(B44*$O$4=0,"",INT(CEILING(B44*$O$4,J44))&" "&C44&" "))) | O44: =IF(L44="","",IF($O$4="","",D44&" "&E44))
L45: =IF(I45="","",IF($L$6="mit",IF(B45*I45*$O$4=0,"",B45*I45*$O$4),IF(B45*I45*$O$4=0,"",INT(CEILING(B45*$O$4,J45))*I45))) | M45: =IF(L45="","",G45) | N45: =IF(L45="","",IF($L$6="mit",IF(B45*$O$4=0,"",B45*$O$4&" "&C45&" "),IF(B45*$O$4=0,"",INT(CEILING(B45*$O$4,J45))&" "&C45&" "))) | O45: =IF(L45="","",IF($O$4="","",D45&" "&E45))
L46: =IF(I46="","",IF($L$6="mit",IF(B46*I46*$O$4=0,"",B46*I46*$O$4),IF(B46*I46*$O$4=0,"",INT(CEILING(B46*$O$4,J46))*I46))) | M46: =IF(L46="","",G46) | N46: =IF(L46="","",IF($L$6="mit",IF(B46*$O$4=0,"",B46*$O$4&" "&C46&" "),IF(B46*$O$4=0,"",INT(CEILING(B46*$O$4,J46))&" "&C46&" "))) | O46: =IF(L46="","",IF($O$4="","",D46&" "&E46))
L47: =IF(I47="","",IF($L$6="mit",IF(B47*I47*$O$4=0,"",B47*I47*$O$4),IF(B47*I47*$O$4=0,"",INT(CEILING(B47*$O$4,J47))*I47))) | M47: =IF(L47="","",G47) | N47: =IF(L47="","",IF($L$6="mit",IF(B47*$O$4=0,"",B47*$O$4&" "&C47&" "),IF(B47*$O$4=0,"",INT(CEILING(B47*$O$4,J47))&" "&C47&" "))) | O47: =IF(L47="","",IF($O$4="","",D47&" "&E47))
L48: =IF(I48="","",IF($L$6="mit",IF(B48*I48*$O$4=0,"",B48*I48*$O$4),IF(B48*I48*$O$4=0,"",INT(CEILING(B48*$O$4,J48))*I48))) | M48: =IF(L48="","",G48) | N48: =IF(L48="","",IF($L$6="mit",IF(B48*$O$4=0,"",B48*$O$4&" "&C48&" "),IF(B48*$O$4=0,"",INT(CEILING(B48*$O$4,J48))&" "&C48&" "))) | O48: =IF(L48="","",IF($O$4="","",D48&" "&E48))
L49: =IF(I49="","",IF($L$6="mit",IF(B49*I49*$O$4=0,"",B49*I49*$O$4),IF(B49*I49*$O$4=0,"",INT(CEILING(B49*$O$4,J49))*I49))) | M49: =IF(L49="","",G49) | N49: =IF(L49="","",IF($L$6="mit",IF(B49*$O$4=0,"",B49*$O$4&" "&C49&" "),IF(B49*$O$4=0,"",INT(CEILING(B49*$O$4,J49))&" "&C49&" "))) | O49: =IF(L49="","",IF($O$4="","",D49&" "&E49))
...

Sheet Stückliste (1)
A1: 1 | E1: 2 | I1: 3 | M1: 4 | AG1: 5 | AX1: 6 | BB1: 7
A2: =Eingabe!A7 -> Lfd. Nr. | E2: =Eingabe!B7 -> Stück- zahl | I2: =Eingabe!C7 -> Ein- heit | M2: =Eingabe!D7 -> Benennung | AG2: =Eingabe!F7&" / "&Eingabe!G7 -> Lieferant / Bestellnummer | AX2: =Eingabe!H7 -> MCd | BB2: =Eingabe!K7 -> Bemerkung
A4: =IF(Eingabe!A8="","",Eingabe!A8) -> 1 | E4: =IF(Eingabe!B8="","",Eingabe!B8) -> 40 | I4: =IF(Eingabe!C8="","",Eingabe!C8) -> STK | M4: =IF(Eingabe!D8&""&Eingabe!E8="","",Eingabe!D8&" "&Eingabe!E8) -> Choc V1 Switches SWL1-20, SWR1-20 | AG4: =IF(Eingabe!F8&""&Eingabe!G8="","",Eingabe!F8&" "&Eingabe!G8) -> keeb.supply | AX4: =IF(Eingabe!H8="","",Eingabe!H8) | BB4: =IF(Eingabe!K8="","",Eingabe!K8) -> Ambients Silent Linear Twilight
A5: =IF(Eingabe!A9="","",Eingabe!A9) -> 2 | E5: =IF(Eingabe!B9="","",Eingabe!B9) -> 40 | I5: =IF(Eingabe!C9="","",Eingabe!C9) -> STK | M5: =IF(Eingabe!D9&""&Eingabe!E9="","",Eingabe!D9&" "&Eingabe!E9) -> Kailh-Choc 1350 Hot Swap Sockets SWL1-20, SWR1-20 | AG5: =IF(Eingabe!F9&""&Eingabe!G9="","",Eingabe!F9&" "&Eingabe!G9) -> keeb.supply | AX5: =IF(Eingabe!H9="","",Eingabe!H9) | BB5: =IF(Eingabe!K9="","",Eingabe!K9) -> Choc Kailh hotswap sockets
A6: =IF(Eingabe!A10="","",Eingabe!A10) -> 3 | E6: =IF(Eingabe!B10="","",Eingabe!B10) -> 40 | I6: =IF(Eingabe!C10="","",Eingabe!C10) -> STK | M6: =IF(Eingabe!D10&""&Eingabe!E10="","",Eingabe!D10&" "&Eingabe!E10) -> 1N4148 DL1-20, DR1-20 | AG6: =IF(Eingabe!F10&""&Eingabe!G10="","",Eingabe!F10&" "&Eingabe!G10) -> s-grundner 1N 4148 | AX6: =IF(Eingabe!H10="","",Eingabe!H10) | BB6: =IF(Eingabe!K10="","",Eingabe!K10) -> THT version
A7: =IF(Eingabe!A11="","",Eingabe!A11) -> 4 | E7: =IF(Eingabe!B11="","",Eingabe!B11) -> 2 | I7: =IF(Eingabe!C11="","",Eingabe!C11) -> STK | M7: =IF(Eingabe!D11&""&Eingabe!E11="","",Eingabe!D11&" "&Eingabe!E11) -> Reset Button RSW1,2 | AG7: =IF(Eingabe!F11&""&Eingabe!G11="","",Eingabe!F11&" "&Eingabe!G11) -> keeb.supply SKHLLCA010 | AX7: =IF(Eingabe!H11="","",Eingabe!H11) | BB7: =IF(Eingabe!K11="","",Eingabe!K11) -> Alps
A8: =IF(Eingabe!A12="","",Eingabe!A12) -> 5 | E8: =IF(Eingabe!B12="","",Eingabe!B12) -> 1 | I8: =IF(Eingabe!C12="","",Eingabe!C12) -> STK | M8: =IF(Eingabe!D12&""&Eingabe!E12="","",Eingabe!D12&" "&Eingabe!E12) -> PCB | AG8: =IF(Eingabe!F12&""&Eingabe!G12="","",Eingabe!F12&" "&Eingabe!G12) -> l-langegger | AX8: =IF(Eingabe!H12="","",Eingabe!H12) | BB8: =IF(Eingabe!K12="","",Eingabe!K12) -> PCB-Way via Sammelbestellung
A9: =IF(Eingabe!A13="","",Eingabe!A13) -> 6 | E9: =IF(Eingabe!B13="","",Eingabe!B13) -> 2 | I9: =IF(Eingabe!C13="","",Eingabe!C13) -> STK | M9: =IF(Eingabe!D13&""&Eingabe!E13="","",Eingabe!D13&" "&Eingabe!E13) -> LiPo Akku 3.7V | AG9: =IF(Eingabe!F13&""&Eingabe!G13="","",Eingabe!F13&" "&Eingabe!G13) -> reichelt.de AKKU 30851 | AX9: =IF(Eingabe!H13="","",Eingabe!H13) | BB9: =IF(Eingabe!K13="","",Eingabe!K13) -> 140mAh, L=24.4mm, B=13.1mm, H=6.1mm
A10: =IF(Eingabe!A14="","",Eingabe!A14) -> 7 | E10: =IF(Eingabe!B14="","",Eingabe!B14) -> 3 | I10: =IF(Eingabe!C14="","",Eingabe!C14) -> STK | M10: =IF(Eingabe!D14&""&Eingabe!E14="","",Eingabe!D14&" "&Eingabe!E14) -> Seeed Studio XIAO nRF52840 U1,2 | AG10: =IF(Eingabe!F14&""&Eingabe!G14="","",Eingabe!F14&" "&Eingabe!G14) -> reichelt.de XIAO NRF52840 | AX10: =IF(Eingabe!H14="","",Eingabe!H14) | BB10: =IF(Eingabe!K14="","",Eingabe!K14)
A11: =IF(Eingabe!A15="","",Eingabe!A15) -> 8 | E11: =IF(Eingabe!B15="","",Eingabe!B15) -> 2 | I11: =IF(Eingabe!C15="","",Eingabe!C15) -> STK | M11: =IF(Eingabe!D15&""&Eingabe!E15="","",Eingabe!D15&" "&Eingabe!E15) -> SPST Power Switch PSW1,2 | AG11: =IF(Eingabe!F15&""&Eingabe!G15="","",Eingabe!F15&" "&Eingabe!G15) -> keeb.supply MSK-12C02 | AX11: =IF(Eingabe!H15="","",Eingabe!H15) | BB11: =IF(Eingabe!K15="","",Eingabe!K15) -> Switch Mini 7 Pin 2 Slide Positions
A12: =IF(Eingabe!A16="","",Eingabe!A16) -> 9 | E12: =IF(Eingabe!B16="","",Eingabe!B16) -> 4 | I12: =IF(Eingabe!C16="","",Eingabe!C16) -> STK | M12: =IF(Eingabe!D16&""&Eingabe!E16="","",Eingabe!D16&" "&Eingabe!E16) -> Gummi Füße | AG12: =IF(Eingabe!F16&""&Eingabe!G16="","",Eingabe!F16&" "&Eingabe!G16) -> amazon.de | AX12: =IF(Eingabe!H16="","",Eingabe!H16) | BB12: =IF(Eingabe!K16="","",Eingabe!K16) -> Round Silicone Rubber Feet
A13: =IF(Eingabe!A17="","",Eingabe!A17) -> 1 | E13: =IF(Eingabe!B17="","",Eingabe!B17) | I13: =IF(Eingabe!C17="","",Eingabe!C17) | M13: =IF(Eingabe!D17&""&Eingabe!E17="","",Eingabe!D17&" "&Eingabe!E17) | AG13: =IF(Eingabe!F17&""&Eingabe!G17="","",Eingabe!F17&" "&Eingabe!G17) | AX13: =IF(Eingabe!H17="","",Eingabe!H17) | BB13: =IF(Eingabe!K17="","",Eingabe!K17)
A14: =IF(Eingabe!A18="","",Eingabe!A18) -> 11 | E14: =IF(Eingabe!B18="","",Eingabe!B18) | I14: =IF(Eingabe!C18="","",Eingabe!C18) | M14: =IF(Eingabe!D18&""&Eingabe!E18="","",Eingabe!D18&" "&Eingabe!E18) | AG14: =IF(Eingabe!F18&""&Eingabe!G18="","",Eingabe!F18&" "&Eingabe!G18) | AX14: =IF(Eingabe!H18="","",Eingabe!H18) | BB14: =IF(Eingabe!K18="","",Eingabe!K18)
A15: =IF(Eingabe!A19="","",Eingabe!A19) -> 12 | E15: =IF(Eingabe!B19="","",Eingabe!B19) | I15: =IF(Eingabe!C19="","",Eingabe!C19) | M15: =IF(Eingabe!D19&""&Eingabe!E19="","",Eingabe!D19&" "&Eingabe!E19) | AG15: =IF(Eingabe!F19&""&Eingabe!G19="","",Eingabe!F19&" "&Eingabe!G19) | AX15: =IF(Eingabe!H19="","",Eingabe!H19) | BB15: =IF(Eingabe!K19="","",Eingabe!K19)
... A28: =IF(Eingabe!A32="","",Eingabe!A32) -> 25 | E28: =IF(Eingabe!B32="","",Eingabe!B32) | I28: =IF(Eingabe!C32="","",Eingabe!C32) | M28: =IF(Eingabe!D32&""&Eingabe!E32="","",Eingabe!D32&" "&Eingabe!E32) | AG28: =IF(Eingabe!F32&""&Eingabe!G32="","",Eingabe!F32&" "&Eingabe!G32) | AX28: =IF(Eingabe!H32="","",Eingabe!H32) | BB28: =IF(Eingabe!K32="","",Eingabe!K32)
A29: Sachnummer, Dateiname: | W29: Name: | AS29: Toleranz: | BB29: Werkstoff:
A30: =IF(Eingabe!O2="","",Eingabe!O2) | W30: =IF(Eingabe!E3="","",Eingabe!E3) -> Simon Grundner | AS30: =IF(Eingabe!I1="","",Eingabe!I1) | BB30: =IF(Eingabe!I2="","",Eingabe!I2) -> FR4
W32: ID-Nr.: | AG32: Gez.: | AK32: Geprüft: | AO32: Betreuer: | AS32: Dokumentart: | BI32: Freigabe:
W33: =IF(CONCATENATE(Eingabe!E1," ", Eingabe!E2)="","",CONCATENATE(Eingabe!E1," ", Eingabe!E2)) | AG33: =IF(Eingabe!E4="","",Eingabe!E4) -> GruS | AK33: =IF(Eingabe!I3="","",Eingabe!I3) | AO33: =IF(Eingabe!I4="","",Eingabe!I4) | AS33: =IF(Eingabe!L1="","",Eingabe!L1) -> Stückliste | BI33: =IF(Eingabe!I5="","",Eingabe!I5)
W35: Benennung: | AS35: Version: | AZ35: Revision: | BE35: Dokumentenstatus:
W36: =IF(Eingabe!E5="","",Eingabe!E5) -> TOTEM - Bluetooth | AS36: =IF(Eingabe!L3="","",Eingabe!L3) -> 1.0 | AZ36: =IF(Eingabe!L4="","",Eingabe!L4) -> 1 | BE36: =IF(Eingabe!L5="","",Eingabe!L5) -> Fertigung
A37: HTBLuVA Salzburg
AS38: Maßstab: | AW38: Spr.: | AZ38: Datum: | BI38: Blatt: | BL38: Blätter:
A39: =IF(Eingabe!M6="","",Eingabe!M6) -> Technische Informatik | W39: =IF(Eingabe!E6="","",Eingabe!E6) -> 40 Key Split Ergomech KB | AS39: =IF(Eingabe!L6="","",Eingabe!L6) -> ohne | AW39: =IF(Eingabe!I6="","",Eingabe!I6) -> DE | AZ39: =IF(Eingabe!L2="","",Eingabe!L2) -> 45824 | BI39: 1 | BL39: =(5-(IF(Eingabe!$C$33="","1","0"))-(IF(Eingabe!$C$58="","1","0"))-(IF(Eingabe!$C$83="","1","0"))-(IF(Eingabe!$C$108="","1","0"))) -> 1

Sheet Stückliste (2)
A1: 1 | E1: 2 | I1: 3 | M1: 4 | AG1: 5 | AX1: 6 | BB1: 7
A2: =Eingabe!A7 -> Lfd. Nr. | E2: =Eingabe!B7 -> Stück- zahl | I2: =Eingabe!C7 -> Ein- heit | M2: =Eingabe!D7 -> Benennung | AG2: =Eingabe!F7&" / "&Eingabe!G7 -> Lieferant / Bestellnummer | AX2: =Eingabe!H7 -> MCd | BB2: =Eingabe!K7 -> Bemerkung
A4: =IF(Eingabe!A33="","",Eingabe!A33) -> 26 | E4: =IF(Eingabe!B33="","",Eingabe!B33) | I4: =IF(Eingabe!C33="","",Eingabe!C33) | M4: =IF(Eingabe!D33&""&Eingabe!E33="","",Eingabe!D33&" "&Eingabe!E33) | AG4: =IF(Eingabe!F33&""&Eingabe!G33="","",Eingabe!F33&" "&Eingabe!G33) | AX4: =IF(Eingabe!H33="","",Eingabe!H33) | BB4: =IF(Eingabe!K33="","",Eingabe!K33)
A5: =IF(Eingabe!A34="","",Eingabe!A34) -> 27 | E5: =IF(Eingabe!B34="","",Eingabe!B34) | I5: =IF(Eingabe!C34="","",Eingabe!C34) | M5: =IF(Eingabe!D34&""&Eingabe!E34="","",Eingabe!D34&" "&Eingabe!E34) | AG5: =IF(Eingabe!F34&""&Eingabe!G34="","",Eingabe!F34&" "&Eingabe!G34) | AX5: =IF(Eingabe!H34="","",Eingabe!H34) | BB5: =IF(Eingabe!K34="","",Eingabe!K34)
A6: =IF(Eingabe!A35="","",Eingabe!A35) -> 28 | E6: =IF(Eingabe!B35="","",Eingabe!B35) | I6: =IF(Eingabe!C35="","",Eingabe!C35) | M6: =IF(Eingabe!D35&""&Eingabe!E35="","",Eingabe!D35&" "&Eingabe!E35) | AG6: =IF(Eingabe!F35&""&Eingabe!G35="","",Eingabe!F35&" "&Eingabe!G35) | AX6: =IF(Eingabe!H35="","",Eingabe!H35) | BB6: =IF(Eingabe!K35="","",Eingabe!K35)
A7: =IF(Eingabe!A36="","",Eingabe!A36) -> 29 | E7: =IF(Eingabe!B36="","",Eingabe!B36) | I7: =IF(Eingabe!C36="","",Eingabe!C36) | M7: =IF(Eingabe!D36&""&Eingabe!E36="","",Eingabe!D36&" "&Eingabe!E36) | AG7: =IF(Eingabe!F36&""&Eingabe!G36="","",Eingabe!F36&" "&Eingabe!G36) | AX7: =IF(Eingabe!H36="","",Eingabe!H36) | BB7: =IF(Eingabe!K36="","",Eingabe!K36)
A8: =IF(Eingabe!A37="","",Eingabe!A37) -> 30 | E8: =IF(Eingabe!B37="","",Eingabe!B37) | I8: =IF(Eingabe!C37="","",Eingabe!C37) | M8: =IF(Eingabe!D37&""&Eingabe!E37="","",Eingabe!D37&" "&Eingabe!E37) | AG8: =IF(Eingabe!F37&""&Eingabe!G37="","",Eingabe!F37&" "&Eingabe!G37) | AX8: =IF(Eingabe!H37="","",Eingabe!H37) | BB8: =IF(Eingabe!K37="","",Eingabe!K37)
A9: =IF(Eingabe!A38="","",Eingabe!A38) -> 31 | E9: =IF(Eingabe!B38="","",Eingabe!B38) | I9: =IF(Eingabe!C38="","",Eingabe!C38) | M9: =IF(Eingabe!D38&""&Eingabe!E38="","",Eingabe!D38&" "&Eingabe!E38) | AG9: =IF(Eingabe!F38&""&Eingabe!G38="","",Eingabe!F38&" "&Eingabe!G38) | AX9: =IF(Eingabe!H38="","",Eingabe!H38) | BB9: =IF(Eingabe!K38="","",Eingabe!K38)
A10: =IF(Eingabe!A39="","",Eingabe!A39) | E10: =IF(Eingabe!B39="","",Eingabe!B39) | I10: =IF(Eingabe!C39="","",Eingabe!C39) | M10: =IF(Eingabe!D39&""&Eingabe!E39="","",Eingabe!D39&" "&Eingabe!E39) | AG10: =IF(Eingabe!F39&""&Eingabe!G39="","",Eingabe!F39&" "&Eingabe!G39) | AX10: =IF(Eingabe!H39="","",Eingabe!H39) | BB10: =IF(Eingabe!K39="","",Eingabe!K39)
A11: =IF(Eingabe!A40="","",Eingabe!A40) | E11: =IF(Eingabe!B40="","",Eingabe!B40) | I11: =IF(Eingabe!C40="","",Eingabe!C40) | M11: =IF(Eingabe!D40&""&Eingabe!E40="","",Eingabe!D40&" "&Eingabe!E40) | AG11: =IF(Eingabe!F40&""&Eingabe!G40="","",Eingabe!F40&" "&Eingabe!G40) | AX11: =IF(Eingabe!H40="","",Eingabe!H40) | BB11: =IF(Eingabe!K40="","",Eingabe!K40)
A12: =IF(Eingabe!A41="","",Eingabe!A41) | E12: =IF(Eingabe!B41="","",Eingabe!B41) | I12: =IF(Eingabe!C41="","",Eingabe!C41) | M12: =IF(Eingabe!D41&""&Eingabe!E41="","",Eingabe!D41&" "&Eingabe!E41) | AG12: =IF(Eingabe!F41&""&Eingabe!G41="","",Eingabe!F41&" "&Eingabe!G41) | AX12: =IF(Eingabe!H41="","",Eingabe!H41) | BB12: =IF(Eingabe!K41="","",Eingabe!K41)
A13: =IF(Eingabe!A42="","",Eingabe!A42) | E13: =IF(Eingabe!B42="","",Eingabe!B42) | I13: =IF(Eingabe!C42="","",Eingabe!C42) | M13: =IF(Eingabe!D42&""&Eingabe!E42="","",Eingabe!D42&" "&Eingabe!E42) | AG13: =IF(Eingabe!F42&""&Eingabe!G42="","",Eingabe!F42&" "&Eingabe!G42) | AX13: =IF(Eingabe!H42="","",Eingabe!H42) | BB13: =IF(Eingabe!K42="","",Eingabe!K42)
A14: =IF(Eingabe!A43="","",Eingabe!A43) | E14: =IF(Eingabe!B43="","",Eingabe!B43) | I14: =IF(Eingabe!C43="","",Eingabe!C43) | M14: =IF(Eingabe!D43&""&Eingabe!E43="","",Eingabe!D43&" "&Eingabe!E43) | AG14: =IF(Eingabe!F43&""&Eingabe!G43="","",Eingabe!F43&" "&Eingabe!G43) | AX14: =IF(Eingabe!H43="","",Eingabe!H43) | BB14: =IF(Eingabe!K43="","",Eingabe!K43)
A15: =IF(Eingabe!A44="","",Eingabe!A44) | E15: =IF(Eingabe!B44="","",Eingabe!B44) | I15: =IF(Eingabe!C44="","",Eingabe!C44) | M15: =IF(Eingabe!D44&""&Eingabe!E44="","",Eingabe!D44&" "&Eingabe!E44) | AG15: =IF(Eingabe!F44&""&Eingabe!G44="","",Eingabe!F44&" "&Eingabe!G44) | AX15: =IF(Eingabe!H44="","",Eingabe!H44) | BB15: =IF(Eingabe!K44="","",Eingabe!K44)
... A28: =IF(Eingabe!A57="","",Eingabe!A57) | E28: =IF(Eingabe!B57="","",Eingabe!B57) | I28: =IF(Eingabe!C57="","",Eingabe!C57) | M28: =IF(Eingabe!D57&""&Eingabe!E57="","",Eingabe!D57&" "&Eingabe!E57) | AG28: =IF(Eingabe!F57&""&Eingabe!G57="","",Eingabe!F57&" "&Eingabe!G57) | AX28: =IF(Eingabe!H57="","",Eingabe!H57) | BB28: =IF(Eingabe!K57="","",Eingabe!K57)
A29: Sachnummer, Dateiname: | W29: Name: | AS29: Toleranz: | BB29: Werkstoff:
A30: =IF(Eingabe!O2="","",Eingabe!O2) | W30: =IF(Eingabe!E3="","",Eingabe!E3) -> Simon Grundner | AS30: =IF(Eingabe!I1="","",Eingabe!I1) | BB30: =IF(Eingabe!I2="","",Eingabe!I2) -> FR4
W32: ID-Nr.: | AG32: Gez.: | AK32: Geprüft: | AO32: Betreuer: | AS32: Dokumentart: | BI32: Freigabe:
W33: =IF(CONCATENATE(Eingabe!E1," ", Eingabe!E2)="","",CONCATENATE(Eingabe!E1," ", Eingabe!E2)) | AG33: =IF(Eingabe!E4="","",Eingabe!E4) -> GruS | AK33: =IF(Eingabe!I3="","",Eingabe!I3) | AO33: =IF(Eingabe!I4="","",Eingabe!I4) | AS33: =IF(Eingabe!L1="","",Eingabe!L1) -> Stückliste | BI33: =IF(Eingabe!I5="","",Eingabe!I5)
W35: Benennung: | AS35: Version: | AZ35: Revision: | BE35: Dokumentenstatus:
W36: =IF(Eingabe!E5="","",Eingabe!E5) -> TOTEM - Bluetooth | AS36: =IF(Eingabe!L3="","",Eingabe!L3) -> 1.0 | AZ36: =IF(Eingabe!L4="","",Eingabe!L4) -> 1 | BE36: =IF(Eingabe!L5="","",Eingabe!L5) -> Fertigung
A37: HTBLuVA Salzburg
AS38: Maßstab: | AW38: Spr.: | AZ38: Datum: | BI38: Blatt: | BL38: Blätter:
A39: =IF(Eingabe!M6="","",Eingabe!M6) -> Technische Informatik | W39: =IF(Eingabe!E6="","",Eingabe!E6) -> 40 Key Split Ergomech KB | AS39: =IF(Eingabe!L6="","",Eingabe!L6) -> ohne | AW39: =IF(Eingabe!I6="","",Eingabe!I6) -> DE | AZ39: =IF(Eingabe!L2="","",Eingabe!L2) -> 45824 | BI39: 2 | BL39: =(5-(IF(Eingabe!$C$33="","1","0"))-(IF(Eingabe!$C$58="","1","0"))-(IF(Eingabe!$C$83="","1","0"))-(IF(Eingabe!$C$108="","1","0"))) -> 1

Sheet Stückliste (3)
A1: 1 | E1: 2 | I1: 3 | M1: 4 | AG1: 5 | AX1: 6 | BB1: 7
A2: =Eingabe!A7 -> Lfd. Nr. | E2: =Eingabe!B7 -> Stück- zahl | I2: =Eingabe!C7 -> Ein- heit | M2: =Eingabe!D7 -> Benennung | AG2: =Eingabe!F7&" / "&Eingabe!G7 -> Lieferant / Bestellnummer | AX2: =Eingabe!H7 -> MCd | BB2: =Eingabe!K7 -> Bemerkung
A4: =IF(Eingabe!A58="","",Eingabe!A58) | E4: =IF(Eingabe!B58="","",Eingabe!B58) | I4: =IF(Eingabe!C58="","",Eingabe!C58) | M4: =IF(Eingabe!D58&""&Eingabe!E58="","",Eingabe!D58&" "&Eingabe!E58) | AG4: =IF(Eingabe!F58&""&Eingabe!G58="","",Eingabe!F58&" "&Eingabe!G58) | AX4: =IF(Eingabe!H58="","",Eingabe!H58) | BB4: =IF(Eingabe!K58="","",Eingabe!K58)
A5: =IF(Eingabe!A59="","",Eingabe!A59) | E5: =IF(Eingabe!B59="","",Eingabe!B59) | I5: =IF(Eingabe!C59="","",Eingabe!C59) | M5: =IF(Eingabe!D59&""&Eingabe!E59="","",Eingabe!D59&" "&Eingabe!E59) | AG5: =IF(Eingabe!F59&""&Eingabe!G59="","",Eingabe!F59&" "&Eingabe!G59) | AX5: =IF(Eingabe!H59="","",Eingabe!H59) | BB5: =IF(Eingabe!K59="","",Eingabe!K59)
A6: =IF(Eingabe!A60="","",Eingabe!A60) | E6: =IF(Eingabe!B60="","",Eingabe!B60) | I6: =IF(Eingabe!C60="","",Eingabe!C60) | M6: =IF(Eingabe!D60&""&Eingabe!E60="","",Eingabe!D60&" "&Eingabe!E60) | AG6: =IF(Eingabe!F60&""&Eingabe!G60="","",Eingabe!F60&" "&Eingabe!G60) | AX6: =IF(Eingabe!H60="","",Eingabe!H60) | BB6: =IF(Eingabe!K60="","",Eingabe!K60)
A7: =IF(Eingabe!A61="","",Eingabe!A61) | E7: =IF(Eingabe!B61="","",Eingabe!B61) | I7: =IF(Eingabe!C61="","",Eingabe!C61) | M7: =IF(Eingabe!D61&""&Eingabe!E61="","",Eingabe!D61&" "&Eingabe!E61) | AG7: =IF(Eingabe!F61&""&Eingabe!G61="","",Eingabe!F61&" "&Eingabe!G61) | AX7: =IF(Eingabe!H61="","",Eingabe!H61) | BB7: =IF(Eingabe!K61="","",Eingabe!K61)
A8: =IF(Eingabe!A62="","",Eingabe!A62) | E8: =IF(Eingabe!B62="","",Eingabe!B62) | I8: =IF(Eingabe!C62="","",Eingabe!C62) | M8: =IF(Eingabe!D62&""&Eingabe!E62="","",Eingabe!D62&" "&Eingabe!E62) | AG8: =IF(Eingabe!F62&""&Eingabe!G62="","",Eingabe!F62&" "&Eingabe!G62) | AX8: =IF(Eingabe!H62="","",Eingabe!H62) | BB8: =IF(Eingabe!K62="","",Eingabe!K62)
A9: =IF(Eingabe!A63="","",Eingabe!A63) | E9: =IF(Eingabe!B63="","",Eingabe!B63) | I9: =IF(Eingabe!C63="","",Eingabe!C63) | M9: =IF(Eingabe!D63&""&Eingabe!E63="","",Eingabe!D63&" "&Eingabe!E63) | AG9: =IF(Eingabe!F63&""&Eingabe!G63="","",Eingabe!F63&" "&Eingabe!G63) | AX9: =IF(Eingabe!H63="","",Eingabe!H63) | BB9: =IF(Eingabe!K63="","",Eingabe!K63)
A10: =IF(Eingabe!A64="","",Eingabe!A64) | E10: =IF(Eingabe!B64="","",Eingabe!B64) | I10: =IF(Eingabe!C64="","",Eingabe!C64) | M10: =IF(Eingabe!D64&""&Eingabe!E64="","",Eingabe!D64&" "&Eingabe!E64) | AG10: =IF(Eingabe!F64&""&Eingabe!G64="","",Eingabe!F64&" "&Eingabe!G64) | AX10: =IF(Eingabe!H64="","",Eingabe!H64) | BB10: =IF(Eingabe!K64="","",Eingabe!K64)
A11: =IF(Eingabe!A65="","",Eingabe!A65) | E11: =IF(Eingabe!B65="","",Eingabe!B65) | I11: =IF(Eingabe!C65="","",Eingabe!C65) | M11: =IF(Eingabe!D65&""&Eingabe!E65="","",Eingabe!D65&" "&Eingabe!E65) | AG11: =IF(Eingabe!F65&""&Eingabe!G65="","",Eingabe!F65&" "&Eingabe!G65) | AX11: =IF(Eingabe!H65="","",Eingabe!H65) | BB11: =IF(Eingabe!K65="","",Eingabe!K65)
A12: =IF(Eingabe!A66="","",Eingabe!A66) | E12: =IF(Eingabe!B66="","",Eingabe!B66) | I12: =IF(Eingabe!C66="","",Eingabe!C66) | M12: =IF(Eingabe!D66&""&Eingabe!E66="","",Eingabe!D66&" "&Eingabe!E66) | AG12: =IF(Eingabe!F66&""&Eingabe!G66="","",Eingabe!F66&" "&Eingabe!G66) | AX12: =IF(Eingabe!H66="","",Eingabe!H66) | BB12: =IF(Eingabe!K66="","",Eingabe!K66)
A13: =IF(Eingabe!A67="","",Eingabe!A67) | E13: =IF(Eingabe!B67="","",Eingabe!B67) | I13: =IF(Eingabe!C67="","",Eingabe!C67) | M13: =IF(Eingabe!D67&""&Eingabe!E67="","",Eingabe!D67&" "&Eingabe!E67) | AG13: =IF(Eingabe!F67&""&Eingabe!G67="","",Eingabe!F67&" "&Eingabe!G67) | AX13: =IF(Eingabe!H67="","",Eingabe!H67) | BB13: =IF(Eingabe!K67="","",Eingabe!K67)
A14: =IF(Eingabe!A68="","",Eingabe!A68) | E14: =IF(Eingabe!B68="","",Eingabe!B68) | I14: =IF(Eingabe!C68="","",Eingabe!C68) | M14: =IF(Eingabe!D68&""&Eingabe!E68="","",Eingabe!D68&" "&Eingabe!E68) | AG14: =IF(Eingabe!F68&""&Eingabe!G68="","",Eingabe!F68&" "&Eingabe!G68) | AX14: =IF(Eingabe!H68="","",Eingabe!H68) | BB14: =IF(Eingabe!K68="","",Eingabe!K68)
A15: =IF(Eingabe!A69="","",Eingabe!A69) | E15: =IF(Eingabe!B69="","",Eingabe!B69) | I15: =IF(Eingabe!C69="","",Eingabe!C69) | M15: =IF(Eingabe!D69&""&Eingabe!E69="","",Eingabe!D69&" "&Eingabe!E69) | AG15: =IF(Eingabe!F69&""&Eingabe!G69="","",Eingabe!F69&" "&Eingabe!G69) | AX15: =IF(Eingabe!H69="","",Eingabe!H69) | BB15: =IF(Eingabe!K69="","",Eingabe!K69)
... A28: =IF(Eingabe!A82="","",Eingabe!A82) | E28: =IF(Eingabe!B82="","",Eingabe!B82) | I28: =IF(Eingabe!C82="","",Eingabe!C82) | M28: =IF(Eingabe!D82&""&Eingabe!E82="","",Eingabe!D82&" "&Eingabe!E82) | AG28: =IF(Eingabe!F82&""&Eingabe!G82="","",Eingabe!F82&" "&Eingabe!G82) | AX28: =IF(Eingabe!H82="","",Eingabe!H82) | BB28: =IF(Eingabe!K82="","",Eingabe!K82)
A29: Sachnummer, Dateiname: | W29: Name: | AS29: Toleranz: | BB29: Werkstoff:
A30: =IF(Eingabe!O2="","",Eingabe!O2) | W30: =IF(Eingabe!E3="","",Eingabe!E3) -> Simon Grundner | AS30: =IF(Eingabe!I1="","",Eingabe!I1) | BB30: =IF(Eingabe!I2="","",Eingabe!I2) -> FR4
W32: ID-Nr.: | AG32: Gez.: | AK32: Geprüft: | AO32: Betreuer: | AS32: Dokumentart: | BI32: Freigabe:
W33: =IF(CONCATENATE(Eingabe!E1," ", Eingabe!E2)="","",CONCATENATE(Eingabe!E1," ", Eingabe!E2)) | AG33: =IF(Eingabe!E4="","",Eingabe!E4) -> GruS | AK33: =IF(Eingabe!I3="","",Eingabe!I3) | AO33: =IF(Eingabe!I4="","",Eingabe!I4) | AS33: =IF(Eingabe!L1="","",Eingabe!L1) -> Stückliste | BI33: =IF(Eingabe!I5="","",Eingabe!I5)
W35: Benennung: | AS35: Version: | AZ35: Revision: | BE35: Dokumentenstatus:
W36: =IF(Eingabe!E5="","",Eingabe!E5) -> TOTEM - Bluetooth | AS36: =IF(Eingabe!L3="","",Eingabe!L3) -> 1.0 | AZ36: =IF(Eingabe!L4="","",Eingabe!L4) -> 1 | BE36: =IF(Eingabe!L5="","",Eingabe!L5) -> Fertigung
A37: HTBLuVA Salzburg
AS38: Maßstab: | AW38: Spr.: | AZ38: Datum: | BI38: Blatt: | BL38: Blätter:
A39: =IF(Eingabe!M6="","",Eingabe!M6) -> Technische Informatik | W39: =IF(Eingabe!E6="","",Eingabe!E6) -> 40 Key Split Ergomech KB | AS39: =IF(Eingabe!L6="","",Eingabe!L6) -> ohne | AW39: =IF(Eingabe!I6="","",Eingabe!I6) -> DE | AZ39: =IF(Eingabe!L2="","",Eingabe!L2) -> 45824 | BI39: 3 | BL39: =(5-(IF(Eingabe!$C$33="","1","0"))-(IF(Eingabe!$C$58="","1","0"))-(IF(Eingabe!$C$83="","1","0"))-(IF(Eingabe!$C$108="","1","0"))) -> 1

Sheet Stückliste (4)
A1: 1 | E1: 2 | I1: 3 | M1: 4 | AG1: 5 | AX1: 6 | BB1: 7
A2: =Eingabe!A7 -> Lfd. Nr. | E2: =Eingabe!B7 -> Stück- zahl | I2: =Eingabe!C7 -> Ein- heit | M2: =Eingabe!D7 -> Benennung | AG2: =Eingabe!F7&" / "&Eingabe!G7 -> Lieferant / Bestellnummer | AX2: =Eingabe!H7 -> MCd | BB2: =Eingabe!K7 -> Bemerkung
A4: =IF(Eingabe!A83="","",Eingabe!A83) | E4: =IF(Eingabe!B83="","",Eingabe!B83) | I4: =IF(Eingabe!C83="","",Eingabe!C83) | M4: =IF(Eingabe!D83&""&Eingabe!E83="","",Eingabe!D83&" "&Eingabe!E83) | AG4: =IF(Eingabe!F83&""&Eingabe!G83="","",Eingabe!F83&" "&Eingabe!G83) | AX4: =IF(Eingabe!H83="","",Eingabe!H83) | BB4: =IF(Eingabe!K83="","",Eingabe!K83)
A5: =IF(Eingabe!A84="","",Eingabe!A84) | E5: =IF(Eingabe!B84="","",Eingabe!B84) | I5: =IF(Eingabe!C84="","",Eingabe!C84) | M5: =IF(Eingabe!D84&""&Eingabe!E84="","",Eingabe!D84&" "&Eingabe!E84) | AG5: =IF(Eingabe!F84&""&Eingabe!G84="","",Eingabe!F84&" "&Eingabe!G84) | AX5: =IF(Eingabe!H84="","",Eingabe!H84) | BB5: =IF(Eingabe!K84="","",Eingabe!K84)
A6: =IF(Eingabe!A85="","",Eingabe!A85) | E6: =IF(Eingabe!B85="","",Eingabe!B85) | I6: =IF(Eingabe!C85="","",Eingabe!C85) | M6: =IF(Eingabe!D85&""&Eingabe!E85="","",Eingabe!D85&" "&Eingabe!E85) | AG6: =IF(Eingabe!F85&""&Eingabe!G85="","",Eingabe!F85&" "&Eingabe!G85) | AX6: =IF(Eingabe!H85="","",Eingabe!H85) | BB6: =IF(Eingabe!K85="","",Eingabe!K85)
A7: =IF(Eingabe!A86="","",Eingabe!A86) | E7: =IF(Eingabe!B86="","",Eingabe!B86) | I7: =IF(Eingabe!C86="","",Eingabe!C86) | M7: =IF(Eingabe!D86&""&Eingabe!E86="","",Eingabe!D86&" "&Eingabe!E86) | AG7: =IF(Eingabe!F86&""&Eingabe!G86="","",Eingabe!F86&" "&Eingabe!G86) | AX7: =IF(Eingabe!H86="","",Eingabe!H86) | BB7: =IF(Eingabe!K86="","",Eingabe!K86)
A8: =IF(Eingabe!A87="","",Eingabe!A87) | E8: =IF(Eingabe!B87="","",Eingabe!B87) | I8: =IF(Eingabe!C87="","",Eingabe!C87) | M8: =IF(Eingabe!D87&""&Eingabe!E87="","",Eingabe!D87&" "&Eingabe!E87) | AG8: =IF(Eingabe!F87&""&Eingabe!G87="","",Eingabe!F87&" "&Eingabe!G87) | AX8: =IF(Eingabe!H87="","",Eingabe!H87) | BB8: =IF(Eingabe!K87="","",Eingabe!K87)
A9: =IF(Eingabe!A88="","",Eingabe!A88) | E9: =IF(Eingabe!B88="","",Eingabe!B88) | I9: =IF(Eingabe!C88="","",Eingabe!C88) | M9: =IF(Eingabe!D88&""&Eingabe!E88="","",Eingabe!D88&" "&Eingabe!E88) | AG9: =IF(Eingabe!F88&""&Eingabe!G88="","",Eingabe!F88&" "&Eingabe!G88) | AX9: =IF(Eingabe!H88="","",Eingabe!H88) | BB9: =IF(Eingabe!K88="","",Eingabe!K88)
A10: =IF(Eingabe!A89="","",Eingabe!A89) | E10: =IF(Eingabe!B89="","",Eingabe!B89) | I10: =IF(Eingabe!C89="","",Eingabe!C89) | M10: =IF(Eingabe!D89&""&Eingabe!E89="","",Eingabe!D89&" "&Eingabe!E89) | AG10: =IF(Eingabe!F89&""&Eingabe!G89="","",Eingabe!F89&" "&Eingabe!G89) | AX10: =IF(Eingabe!H89="","",Eingabe!H89) | BB10: =IF(Eingabe!K89="","",Eingabe!K89)
A11: =IF(Eingabe!A90="","",Eingabe!A90) | E11: =IF(Eingabe!B90="","",Eingabe!B90) | I11: =IF(Eingabe!C90="","",Eingabe!C90) | M11: =IF(Eingabe!D90&""&Eingabe!E90="","",Eingabe!D90&" "&Eingabe!E90) | AG11: =IF(Eingabe!F90&""&Eingabe!G90="","",Eingabe!F90&" "&Eingabe!G90) | AX11: =IF(Eingabe!H90="","",Eingabe!H90) | BB11: =IF(Eingabe!K90="","",Eingabe!K90)
A12: =IF(Eingabe!A91="","",Eingabe!A91) | E12: =IF(Eingabe!B91="","",Eingabe!B91) | I12: =IF(Eingabe!C91="","",Eingabe!C91) | M12: =IF(Eingabe!D91&""&Eingabe!E91="","",Eingabe!D91&" "&Eingabe!E91) | AG12: =IF(Eingabe!F91&""&Eingabe!G91="","",Eingabe!F91&" "&Eingabe!G91) | AX12: =IF(Eingabe!H91="","",Eingabe!H91) | BB12: =IF(Eingabe!K91="","",Eingabe!K91)
A13: =IF(Eingabe!A92="","",Eingabe!A92) | E13: =IF(Eingabe!B92="","",Eingabe!B92) | I13: =IF(Eingabe!C92="","",Eingabe!C92) | M13: =IF(Eingabe!D92&""&Eingabe!E92="","",Eingabe!D92&" "&Eingabe!E92) | AG13: =IF(Eingabe!F92&""&Eingabe!G92="","",Eingabe!F92&" "&Eingabe!G92) | AX13: =IF(Eingabe!H92="","",Eingabe!H92) | BB13: =IF(Eingabe!K92="","",Eingabe!K92)
A14: =IF(Eingabe!A93="","",Eingabe!A93) | E14: =IF(Eingabe!B93="","",Eingabe!B93) | I14: =IF(Eingabe!C93="","",Eingabe!C93) | M14: =IF(Eingabe!D93&""&Eingabe!E93="","",Eingabe!D93&" "&Eingabe!E93) | AG14: =IF(Eingabe!F93&""&Eingabe!G93="","",Eingabe!F93&" "&Eingabe!G93) | AX14: =IF(Eingabe!H93="","",Eingabe!H93) | BB14: =IF(Eingabe!K93="","",Eingabe!K93)
A15: =IF(Eingabe!A94="","",Eingabe!A94) | E15: =IF(Eingabe!B94="","",Eingabe!B94) | I15: =IF(Eingabe!C94="","",Eingabe!C94) | M15: =IF(Eingabe!D94&""&Eingabe!E94="","",Eingabe!D94&" "&Eingabe!E94) | AG15: =IF(Eingabe!F94&""&Eingabe!G94="","",Eingabe!F94&" "&Eingabe!G94) | AX15: =IF(Eingabe!H94="","",Eingabe!H94) | BB15: =IF(Eingabe!K94="","",Eingabe!K94)
... A28: =IF(Eingabe!A107="","",Eingabe!A107) | E28: =IF(Eingabe!B107="","",Eingabe!B107) | I28: =IF(Eingabe!C107="","",Eingabe!C107) | M28: =IF(Eingabe!D107&""&Eingabe!E107="","",Eingabe!D107&" "&Eingabe!E107) | AG28: =IF(Eingabe!F107&""&Eingabe!G107="","",Eingabe!F107&" "&Eingabe!G107) | AX28: =IF(Eingabe!H107="","",Eingabe!H107) | BB28: =IF(Eingabe!K107="","",Eingabe!K107)
A29: Sachnummer, Dateiname: | W29: Name: | AS29: Toleranz: | BB29: Werkstoff:
A30: =IF(Eingabe!O2="","",Eingabe!O2) | W30: =IF(Eingabe!E3="","",Eingabe!E3) -> Simon Grundner | AS30: =IF(Eingabe!I1="","",Eingabe!I1) | BB30: =IF(Eingabe!I2="","",Eingabe!I2) -> FR4
W32: ID-Nr.: | AG32: Gez.: | AK32: Geprüft: | AO32: Betreuer: | AS32: Dokumentart: | BI32: Freigabe:
W33: =IF(CONCATENATE(Eingabe!E1," ", Eingabe!E2)="","",CONCATENATE(Eingabe!E1," ", Eingabe!E2)) | AG33: =IF(Eingabe!E4="","",Eingabe!E4) -> GruS | AK33: =IF(Eingabe!I3="","",Eingabe!I3) | AO33: =IF(Eingabe!I4="","",Eingabe!I4) | AS33: =IF(Eingabe!L1="","",Eingabe!L1) -> Stückliste | BI33: =IF(Eingabe!I5="","",Eingabe!I5)
W35: Benennung: | AS35: Version: | AZ35: Revision: | BE35: Dokumentenstatus:
W36: =IF(Eingabe!E5="","",Eingabe!E5) -> TOTEM - Bluetooth | AS36: =IF(Eingabe!L3="","",Eingabe!L3) -> 1.0 | AZ36: =IF(Eingabe!L4="","",Eingabe!L4) -> 1 | BE36: =IF(Eingabe!L5="","",Eingabe!L5) -> Fertigung
A37: HTBLuVA Salzburg
AS38: Maßstab: | AW38: Spr.: | AZ38: Datum: | BI38: Blatt: | BL38: Blätter:
A39: =IF(Eingabe!M6="","",Eingabe!M6) -> Technische Informatik | W39: =IF(Eingabe!E6="","",Eingabe!E6) -> 40 Key Split Ergomech KB | AS39: =IF(Eingabe!L6="","",Eingabe!L6) -> ohne | AW39: =IF(Eingabe!I6="","",Eingabe!I6) -> DE | AZ39: =IF(Eingabe!L2="","",Eingabe!L2) -> 45824 | BI39: 4 | BL39: =(5-(IF(Eingabe!$C$33="","1","0"))-(IF(Eingabe!$C$58="","1","0"))-(IF(Eingabe!$C$83="","1","0"))-(IF(Eingabe!$C$108="","1","0"))) -> 1

Sheet Stückliste (5)
A1: 1 | E1: 2 | I1: 3 | M1: 4 | AG1: 5 | AX1: 6 | BB1: 7
A2: =Eingabe!A7 -> Lfd. Nr. | E2: =Eingabe!B7 -> Stück- zahl | I2: =Eingabe!C7 -> Ein- heit | M2: =Eingabe!D7 -> Benennung | AG2: =Eingabe!F7&" / "&Eingabe!G7 -> Lieferant / Bestellnummer | AX2: =Eingabe!H7 -> MCd | BB2: =Eingabe!K7 -> Bemerkung
A4: =IF(Eingabe!A108="","",Eingabe!A108) | E4: =IF(Eingabe!B108="","",Eingabe!B108) | I4: =IF(Eingabe!C108="","",Eingabe!C108) | M4: =IF(Eingabe!D108&""&Eingabe!E108="","",Eingabe!D108&" "&Eingabe!E108) | AG4: =IF(Eingabe!F108&""&Eingabe!G108="","",Eingabe!F108&" "&Eingabe!G108) | AX4: =IF(Eingabe!H108="","",Eingabe!H108) | BB4: =IF(Eingabe!K108="","",Eingabe!K108)
A5: =IF(Eingabe!A109="","",Eingabe!A109) | E5: =IF(Eingabe!B109="","",Eingabe!B109) | I5: =IF(Eingabe!C109="","",Eingabe!C109) | M5: =IF(Eingabe!D109&""&Eingabe!E109="","",Eingabe!D109&" "&Eingabe!E109) | AG5: =IF(Eingabe!F109&""&Eingabe!G109="","",Eingabe!F109&" "&Eingabe!G109) | AX5: =IF(Eingabe!H109="","",Eingabe!H109) | BB5: =IF(Eingabe!K109="","",Eingabe!K109)
A6: =IF(Eingabe!A110="","",Eingabe!A110) | E6: =IF(Eingabe!B110="","",Eingabe!B110) | I6: =IF(Eingabe!C110="","",Eingabe!C110) | M6: =IF(Eingabe!D110&""&Eingabe!E110="","",Eingabe!D110&" "&Eingabe!E110) | AG6: =IF(Eingabe!F110&""&Eingabe!G110="","",Eingabe!F110&" "&Eingabe!G110) | AX6: =IF(Eingabe!H110="","",Eingabe!H110) | BB6: =IF(Eingabe!K110="","",Eingabe!K110)
A7: =IF(Eingabe!A111="","",Eingabe!A111) | E7: =IF(Eingabe!B111="","",Eingabe!B111) | I7: =IF(Eingabe!C111="","",Eingabe!C111) | M7: =IF(Eingabe!D111&""&Eingabe!E111="","",Eingabe!D111&" "&Eingabe!E111) | AG7: =IF(Eingabe!F111&""&Eingabe!G111="","",Eingabe!F111&" "&Eingabe!G111) | AX7: =IF(Eingabe!H111="","",Eingabe!H111) | BB7: =IF(Eingabe!K111="","",Eingabe!K111)
A8: =IF(Eingabe!A112="","",Eingabe!A112) | E8: =IF(Eingabe!B112="","",Eingabe!B112) | I8: =IF(Eingabe!C112="","",Eingabe!C112) | M8: =IF(Eingabe!D112&""&Eingabe!E112="","",Eingabe!D112&" "&Eingabe!E112) | AG8: =IF(Eingabe!F112&""&Eingabe!G112="","",Eingabe!F112&" "&Eingabe!G112) | AX8: =IF(Eingabe!H112="","",Eingabe!H112) | BB8: =IF(Eingabe!K112="","",Eingabe!K112)
A9: =IF(Eingabe!A113="","",Eingabe!A113) | E9: =IF(Eingabe!B113="","",Eingabe!B113) | I9: =IF(Eingabe!C113="","",Eingabe!C113) | M9: =IF(Eingabe!D113&""&Eingabe!E113="","",Eingabe!D113&" "&Eingabe!E113) | AG9: =IF(Eingabe!F113&""&Eingabe!G113="","",Eingabe!F113&" "&Eingabe!G113) | AX9: =IF(Eingabe!H113="","",Eingabe!H113) | BB9: =IF(Eingabe!K113="","",Eingabe!K113)
A10: =IF(Eingabe!A114="","",Eingabe!A114) | E10: =IF(Eingabe!B114="","",Eingabe!B114) | I10: =IF(Eingabe!C114="","",Eingabe!C114) | M10: =IF(Eingabe!D114&""&Eingabe!E114="","",Eingabe!D114&" "&Eingabe!E114) | AG10: =IF(Eingabe!F114&""&Eingabe!G114="","",Eingabe!F114&" "&Eingabe!G114) | AX10: =IF(Eingabe!H114="","",Eingabe!H114) | BB10: =IF(Eingabe!K114="","",Eingabe!K114)
A11: =IF(Eingabe!A115="","",Eingabe!A115) | E11: =IF(Eingabe!B115="","",Eingabe!B115) | I11: =IF(Eingabe!C115="","",Eingabe!C115) | M11: =IF(Eingabe!D115&""&Eingabe!E115="","",Eingabe!D115&" "&Eingabe!E115) | AG11: =IF(Eingabe!F115&""&Eingabe!G115="","",Eingabe!F115&" "&Eingabe!G115) | AX11: =IF(Eingabe!H115="","",Eingabe!H115) | BB11: =IF(Eingabe!K115="","",Eingabe!K115)
A12: =IF(Eingabe!A116="","",Eingabe!A116) | E12: =IF(Eingabe!B116="","",Eingabe!B116) | I12: =IF(Eingabe!C116="","",Eingabe!C116) | M12: =IF(Eingabe!D116&""&Eingabe!E116="","",Eingabe!D116&" "&Eingabe!E116) | AG12: =IF(Eingabe!F116&""&Eingabe!G116="","",Eingabe!F116&" "&Eingabe!G116) | AX12: =IF(Eingabe!H116="","",Eingabe!H116) | BB12: =IF(Eingabe!K116="","",Eingabe!K116)
A13: =IF(Eingabe!A117="","",Eingabe!A117) | E13: =IF(Eingabe!B117="","",Eingabe!B117) | I13: =IF(Eingabe!C117="","",Eingabe!C117) | M13: =IF(Eingabe!D117&""&Eingabe!E117="","",Eingabe!D117&" "&Eingabe!E117) | AG13: =IF(Eingabe!F117&""&Eingabe!G117="","",Eingabe!F117&" "&Eingabe!G117) | AX13: =IF(Eingabe!H117="","",Eingabe!H117) | BB13: =IF(Eingabe!K117="","",Eingabe!K117)
A14: =IF(Eingabe!A118="","",Eingabe!A118) | E14: =IF(Eingabe!B118="","",Eingabe!B118) | I14: =IF(Eingabe!C118="","",Eingabe!C118) | M14: =IF(Eingabe!D118&""&Eingabe!E118="","",Eingabe!D118&" "&Eingabe!E118) | AG14: =IF(Eingabe!F118&""&Eingabe!G118="","",Eingabe!F118&" "&Eingabe!G118) | AX14: =IF(Eingabe!H118="","",Eingabe!H118) | BB14: =IF(Eingabe!K118="","",Eingabe!K118)
A15: =IF(Eingabe!A119="","",Eingabe!A119) | E15: =IF(Eingabe!B119="","",Eingabe!B119) | I15: =IF(Eingabe!C119="","",Eingabe!C119) | M15: =IF(Eingabe!D119&""&Eingabe!E119="","",Eingabe!D119&" "&Eingabe!E119) | AG15: =IF(Eingabe!F119&""&Eingabe!G119="","",Eingabe!F119&" "&Eingabe!G119) | AX15: =IF(Eingabe!H119="","",Eingabe!H119) | BB15: =IF(Eingabe!K119="","",Eingabe!K119)
... A28: =IF(Eingabe!A132="","",Eingabe!A132) | E28: =IF(Eingabe!B132="","",Eingabe!B132) | I28: =IF(Eingabe!C132="","",Eingabe!C132) | M28: =IF(Eingabe!D132&""&Eingabe!E132="","",Eingabe!D132&" "&Eingabe!E132) | AG28: =IF(Eingabe!F132&""&Eingabe!G132="","",Eingabe!F132&" "&Eingabe!G132) | AX28: =IF(Eingabe!H132="","",Eingabe!H132) | BB28: =IF(Eingabe!K132="","",Eingabe!K132)
A29: Sachnummer, Dateiname: | W29: Name: | AS29: Toleranz: | BB29: Werkstoff:
A30: =IF(Eingabe!O2="","",Eingabe!O2) | W30: =IF(Eingabe!E3="","",Eingabe!E3) -> Simon Grundner | AS30: =IF(Eingabe!I1="","",Eingabe!I1) | BB30: =IF(Eingabe!I2="","",Eingabe!I2) -> FR4
W32: ID-Nr.: | AG32: Gez.: | AK32: Geprüft: | AO32: Betreuer: | AS32: Dokumentart: | BI32: Freigabe:
W33: =IF(CONCATENATE(Eingabe!E1," ", Eingabe!E2)="","",CONCATENATE(Eingabe!E1," ", Eingabe!E2)) | AG33: =IF(Eingabe!E4="","",Eingabe!E4) -> GruS | AK33: =IF(Eingabe!I3="","",Eingabe!I3) | AO33: =IF(Eingabe!I4="","",Eingabe!I4) | AS33: =IF(Eingabe!L1="","",Eingabe!L1) -> Stückliste | BI33: =IF(Eingabe!I5="","",Eingabe!I5)
W35: Benennung: | AS35: Version: | AZ35: Revision: | BE35: Dokumentenstatus:
W36: =IF(Eingabe!E5="","",Eingabe!E5) -> TOTEM - Bluetooth | AS36: =IF(Eingabe!L3="","",Eingabe!L3) -> 1.0 | AZ36: =IF(Eingabe!L4="","",Eingabe!L4) -> 1 | BE36: =IF(Eingabe!L5="","",Eingabe!L5) -> Fertigung
A37: HTBLuVA Salzburg
AS38: Maßstab: | AW38: Spr.: | AZ38: Datum: | BI38: Blatt: | BL38: Blätter:
A39: =IF(Eingabe!M6="","",Eingabe!M6) -> Technische Informatik | W39: =IF(Eingabe!E6="","",Eingabe!E6) -> 40 Key Split Ergomech KB | AS39: =IF(Eingabe!L6="","",Eingabe!L6) -> ohne | AW39: =IF(Eingabe!I6="","",Eingabe!I6) -> DE | AZ39: =IF(Eingabe!L2="","",Eingabe!L2) -> 45824 | BI39: 5 | BL39: =(5-(IF(Eingabe!$C$33="","1","0"))-(IF(Eingabe!$C$58="","1","0"))-(IF(Eingabe!$C$83="","1","0"))-(IF(Eingabe!$C$108="","1","0"))) -> 1

Sheet Materialkalkulation (1)
A1: 1 | D1: 2 | H1: 3 | L1: 4 | AH1: 5 | BE1: 6
A2: =Eingabe!A7 -> Lfd. Nr. | D2: =Eingabe!B7 -> Stück- zahl | H2: =Eingabe!C7 -> Ein- heit | L2: =Eingabe!D7 -> Benennung | AH2: =Eingabe!F7&" / "&Eingabe!G7 -> Lieferant / Bestellnummer | BE2: Preis
BE3: Einzel | BJ3: Gesamt
A4: =IF(Eingabe!A8="","",Eingabe!A8) -> 1 | D4: =IF(Eingabe!B8="","",Eingabe!B8) -> 40 | H4: =IF(Eingabe!C8="","",Eingabe!C8) -> STK | L4: =IF(Eingabe!D8="","",Eingabe!D8) -> Choc V1 Switches | AH4: =IF(Eingabe!F8&Eingabe!G8="","",Eingabe!F8&" / "&Eingabe!G8) -> keeb.supply / | BE4: =IF(Eingabe!I8="","",Eingabe!I8) -> 0.95 | BJ4: =IF(Eingabe!I8="","",Eingabe!I8*Eingabe!B8) -> 38
A5: =IF(Eingabe!A9="","",Eingabe!A9) -> 2 | D5: =IF(Eingabe!B9="","",Eingabe!B9) -> 40 | H5: =IF(Eingabe!C9="","",Eingabe!C9) -> STK | L5: =IF(Eingabe!D9="","",Eingabe!D9) -> Kailh-Choc 1350 Hot Swap Sockets | AH5: =IF(Eingabe!F9&Eingabe!G9="","",Eingabe!F9&" / "&Eingabe!G9) -> keeb.supply / | BE5: =IF(Eingabe!I9="","",Eingabe!I9) -> 0.22 | BJ5: =IF(Eingabe!I9="","",Eingabe!I9*Eingabe!B9) -> 8.8
A6: =IF(Eingabe!A10="","",Eingabe!A10) -> 3 | D6: =IF(Eingabe!B10="","",Eingabe!B10) -> 40 | H6: =IF(Eingabe!C10="","",Eingabe!C10) -> STK | L6: =IF(Eingabe!D10="","",Eingabe!D10) -> 1N4148 | AH6: =IF(Eingabe!F10&Eingabe!G10="","",Eingabe!F10&" / "&Eingabe!G10) -> s-grundner / 1N 4148 | BE6: =IF(Eingabe!I10="","",Eingabe!I10) -> 0 | BJ6: =IF(Eingabe!I10="","",Eingabe!I10*Eingabe!B10) -> 0
A7: =IF(Eingabe!A11="","",Eingabe!A11) -> 4 | D7: =IF(Eingabe!B11="","",Eingabe!B11) -> 2 | H7: =IF(Eingabe!C11="","",Eingabe!C11) -> STK | L7: =IF(Eingabe!D11="","",Eingabe!D11) -> Reset Button | AH7: =IF(Eingabe!F11&Eingabe!G11="","",Eingabe!F11&" / "&Eingabe!G11) -> keeb.supply / SKHLLCA010 | BE7: =IF(Eingabe!I11="","",Eingabe!I11) -> 0.6 | BJ7: =IF(Eingabe!I11="","",Eingabe!I11*Eingabe!B11) -> 1.2
A8: =IF(Eingabe!A12="","",Eingabe!A12) -> 5 | D8: =IF(Eingabe!B12="","",Eingabe!B12) -> 1 | H8: =IF(Eingabe!C12="","",Eingabe!C12) -> STK | L8: =IF(Eingabe!D12="","",Eingabe!D12) -> PCB | AH8: =IF(Eingabe!F12&Eingabe!G12="","",Eingabe!F12&" / "&Eingabe!G12) -> l-langegger / | BE8: =IF(Eingabe!I12="","",Eingabe!I12) -> 0 | BJ8: =IF(Eingabe!I12="","",Eingabe!I12*Eingabe!B12) -> 0
A9: =IF(Eingabe!A13="","",Eingabe!A13) -> 6 | D9: =IF(Eingabe!B13="","",Eingabe!B13) -> 2 | H9: =IF(Eingabe!C13="","",Eingabe!C13) -> STK | L9: =IF(Eingabe!D13="","",Eingabe!D13) -> LiPo Akku 3.7V | AH9: =IF(Eingabe!F13&Eingabe!G13="","",Eingabe!F13&" / "&Eingabe!G13) -> reichelt.de / AKKU 30851 | BE9: =IF(Eingabe!I13="","",Eingabe!I13) -> 5.3 | BJ9: =IF(Eingabe!I13="","",Eingabe!I13*Eingabe!B13) -> 10.6
A10: =IF(Eingabe!A14="","",Eingabe!A14) -> 7 | D10: =IF(Eingabe!B14="","",Eingabe!B14) -> 3 | H10: =IF(Eingabe!C14="","",Eingabe!C14) -> STK | L10: =IF(Eingabe!D14="","",Eingabe!D14) -> Seeed Studio XIAO nRF52840 | AH10: =IF(Eingabe!F14&Eingabe!G14="","",Eingabe!F14&" / "&Eingabe!G14) -> reichelt.de / XIAO NRF52840 | BE10: =IF(Eingabe!I14="","",Eingabe!I14) -> 12.8 | BJ10: =IF(Eingabe!I14="","",Eingabe!I14*Eingabe!B14) -> 38.4
A11: =IF(Eingabe!A15="","",Eingabe!A15) -> 8 | D11: =IF(Eingabe!B15="","",Eingabe!B15) -> 2 | H11: =IF(Eingabe!C15="","",Eingabe!C15) -> STK | L11: =IF(Eingabe!D15="","",Eingabe!D15) -> SPST Power Switch | AH11: =IF(Eingabe!F15&Eingabe!G15="","",Eingabe!F15&" / "&Eingabe!G15) -> keeb.supply / MSK-12C02 | BE11: =IF(Eingabe!I15="","",Eingabe!I15) -> 0.8 | BJ11: =IF(Eingabe!I15="","",Eingabe!I15*Eingabe!B15) -> 1.6
A12: =IF(Eingabe!A16="","",Eingabe!A16) -> 9 | D12: =IF(Eingabe!B16="","",Eingabe!B16) -> 4 | H12: =IF(Eingabe!C16="","",Eingabe!C16) -> STK | L12: =IF(Eingabe!D16="","",Eingabe!D16) -> Gummi Füße | AH12: =IF(Eingabe!F16&Eingabe!G16="","",Eingabe!F16&" / "&Eingabe!G16) -> amazon.de / | BE12: =IF(Eingabe!I16="","",Eingabe!I16) -> 0.0399 | BJ12: =IF(Eingabe!I16="","",Eingabe!I16*Eingabe!B16) -> 0.1596
A13: =IF(Eingabe!A17="","",Eingabe!A17) -> 1 | D13: =IF(Eingabe!B17="","",Eingabe!B17) | H13: =IF(Eingabe!C17="","",Eingabe!C17) | L13: =IF(Eingabe!D17="","",Eingabe!D17) | AH13: =IF(Eingabe!F17&Eingabe!G17="","",Eingabe!F17&" / "&Eingabe!G17) | BE13: =IF(Eingabe!I17="","",Eingabe!I17) | BJ13: =IF(Eingabe!I17="","",Eingabe!I17*Eingabe!B17)
A14: =IF(Eingabe!A18="","",Eingabe!A18) -> 11 | D14: =IF(Eingabe!B18="","",Eingabe!B18) | H14: =IF(Eingabe!C18="","",Eingabe!C18) | L14: =IF(Eingabe!D18="","",Eingabe!D18) | AH14: =IF(Eingabe!F18&Eingabe!G18="","",Eingabe!F18&" / "&Eingabe!G18) | BE14: =IF(Eingabe!I18="","",Eingabe!I18) | BJ14: =IF(Eingabe!I18="","",Eingabe!I18*Eingabe!B18)
A15: =IF(Eingabe!A19="","",Eingabe!A19) -> 12 | D15: =IF(Eingabe!B19="","",Eingabe!B19) | H15: =IF(Eingabe!C19="","",Eingabe!C19) | L15: =IF(Eingabe!D19="","",Eingabe!D19) | AH15: =IF(Eingabe!F19&Eingabe!G19="","",Eingabe!F19&" / "&Eingabe!G19) | BE15: =IF(Eingabe!I19="","",Eingabe!I19) | BJ15: =IF(Eingabe!I19="","",Eingabe!I19*Eingabe!B19)
... A48: =IF(Eingabe!A52="","",Eingabe!A52) | D48: =IF(Eingabe!B52="","",Eingabe!B52) | H48: =IF(Eingabe!C52="","",Eingabe!C52) | L48: =IF(Eingabe!D52="","",Eingabe!D52) | AH48: =IF(Eingabe!F52&Eingabe!G52="","",Eingabe!F52&" / "&Eingabe!G52) | BE48: =IF(Eingabe!I52="","",Eingabe!I52) | BJ48: =IF(Eingabe!I52="","",Eingabe!I52*Eingabe!B52)
AH49: Übertrag:
AH50: Materialpreis | BE50: =SUM(BJ4:BN48) -> 98.7596
AH51: Materialgemeinkosten (10%) | BE51: =BE50*0.1 -> 9.87596
AH52: Materialverkaufspreis | BE52: =SUM(BE49:BN51) -> 108.63556
A53: Sachnummer, Dateiname: | W53: Name: | AS53: Toleranz: | BB53: Werkstoff:
A54: =IF(Eingabe!O3="","",Eingabe!O3) | W54: =IF(Eingabe!E3="","",Eingabe!E3) -> Simon Grundner | AS54: =IF(Eingabe!I1="","",Eingabe!I1) | BB54: =IF(Eingabe!I2="","",Eingabe!I2) -> FR4
W56: ID-Nr.: | AG56: Gez.: | AK56: Geprüft: | AO56: Betreuer: | AS56: Dokumentart: | BI56: Freigabe:
W57: =IF(CONCATENATE(Eingabe!E1," ", Eingabe!E2)="","",CONCATENATE(Eingabe!E1," ", Eingabe!E2)) | AG57: =IF(Eingabe!E4="","",Eingabe!E4) -> GruS | AK57: =IF(Eingabe!I3="","",Eingabe!I3) | AO57: =IF(Eingabe!I4="","",Eingabe!I4) | AS57: Materialkalkulation | BI57: =IF(Eingabe!I5="","",Eingabe!I5)
W59: Benennung: | AS59: Version: | AZ59: Revision: | BE59: Dokumentenstatus:
W60: =IF(Eingabe!E5="","",Eingabe!E5) -> TOTEM - Bluetooth | AS60: =IF(Eingabe!L3="","",Eingabe!L3) -> 1.0 | AZ60: =IF(Eingabe!L4="","",Eingabe!L4) -> 1 | BE60: =IF(Eingabe!L5="","",Eingabe!L5) -> Fertigung
A61: HTBLuVA Salzburg
AS62: Maßstab: | AW62: Spr.: | AZ62: Datum: | BI62: Blatt: | BL62: Blätter:
A63: =IF(Eingabe!M6="","",Eingabe!M6) -> Technische Informatik | W63: =IF(Eingabe!E6="","",Eingabe!E6) -> 40 Key Split Ergomech KB | AS63: =IF(Eingabe!L6="","",Eingabe!L6) -> ohne | AW63: =IF(Eingabe!I6="","",Eingabe!I6) -> DE | AZ63: =IF(Eingabe!L2="","",Eingabe!L2) -> 45824 | BI63: 1 | BL63: =IF('Materialkalkulation (2)'!L4="","1",IF('Materialkalkulation (3)'!L4="","2","3")) -> 1

Sheet Materialkalkulation (2)
A1: 1 | D1: 2 | H1: 3 | L1: 4 | AH1: 5 | BE1: 6
A2: =Eingabe!A7 -> Lfd. Nr. | D2: =Eingabe!B7 -> Stück- zahl | H2: =Eingabe!C7 -> Ein- heit | L2: =Eingabe!D7 -> Benennung | AH2: =Eingabe!F7&" / "&Eingabe!G7 -> Lieferant / Bestellnummer | BE2: Preis
BE3: Einzel | BJ3: Gesamt
A4: =IF(Eingabe!A53="","",Eingabe!A53) | D4: =IF(Eingabe!B53="","",Eingabe!B53) | H4: =IF(Eingabe!C53="","",Eingabe!C53) | L4: =IF(Eingabe!D53="","",Eingabe!D53) | AH4: =IF(Eingabe!F53&Eingabe!G53="","",Eingabe!F53&" / "&Eingabe!G53) | BE4: =IF(Eingabe!I53="","",Eingabe!I53) | BJ4: =IF(Eingabe!I53="","",Eingabe!I53*Eingabe!B53)
A5: =IF(Eingabe!A54="","",Eingabe!A54) | D5: =IF(Eingabe!B54="","",Eingabe!B54) | H5: =IF(Eingabe!C54="","",Eingabe!C54) | L5: =IF(Eingabe!D54="","",Eingabe!D54) | AH5: =IF(Eingabe!F54&Eingabe!G54="","",Eingabe!F54&" / "&Eingabe!G54) | BE5: =IF(Eingabe!I54="","",Eingabe!I54) | BJ5: =IF(Eingabe!I54="","",Eingabe!I54*Eingabe!B54)
A6: =IF(Eingabe!A55="","",Eingabe!A55) | D6: =IF(Eingabe!B55="","",Eingabe!B55) | H6: =IF(Eingabe!C55="","",Eingabe!C55) | L6: =IF(Eingabe!D55="","",Eingabe!D55) | AH6: =IF(Eingabe!F55&Eingabe!G55="","",Eingabe!F55&" / "&Eingabe!G55) | BE6: =IF(Eingabe!I55="","",Eingabe!I55) | BJ6: =IF(Eingabe!I55="","",Eingabe!I55*Eingabe!B55)
A7: =IF(Eingabe!A56="","",Eingabe!A56) | D7: =IF(Eingabe!B56="","",Eingabe!B56) | H7: =IF(Eingabe!C56="","",Eingabe!C56) | L7: =IF(Eingabe!D56="","",Eingabe!D56) | AH7: =IF(Eingabe!F56&Eingabe!G56="","",Eingabe!F56&" / "&Eingabe!G56) | BE7: =IF(Eingabe!I56="","",Eingabe!I56) | BJ7: =IF(Eingabe!I56="","",Eingabe!I56*Eingabe!B56)
A8: =IF(Eingabe!A57="","",Eingabe!A57) | D8: =IF(Eingabe!B57="","",Eingabe!B57) | H8: =IF(Eingabe!C57="","",Eingabe!C57) | L8: =IF(Eingabe!D57="","",Eingabe!D57) | AH8: =IF(Eingabe!F57&Eingabe!G57="","",Eingabe!F57&" / "&Eingabe!G57) | BE8: =IF(Eingabe!I57="","",Eingabe!I57) | BJ8: =IF(Eingabe!I57="","",Eingabe!I57*Eingabe!B57)
A9: =IF(Eingabe!A58="","",Eingabe!A58) | D9: =IF(Eingabe!B58="","",Eingabe!B58) | H9: =IF(Eingabe!C58="","",Eingabe!C58) | L9: =IF(Eingabe!D58="","",Eingabe!D58) | AH9: =IF(Eingabe!F58&Eingabe!G58="","",Eingabe!F58&" / "&Eingabe!G58) | BE9: =IF(Eingabe!I58="","",Eingabe!I58) | BJ9: =IF(Eingabe!I58="","",Eingabe!I58*Eingabe!B58)
A10: =IF(Eingabe!A59="","",Eingabe!A59) | D10: =IF(Eingabe!B59="","",Eingabe!B59) | H10: =IF(Eingabe!C59="","",Eingabe!C59) | L10: =IF(Eingabe!D59="","",Eingabe!D59) | AH10: =IF(Eingabe!F59&Eingabe!G59="","",Eingabe!F59&" / "&Eingabe!G59) | BE10: =IF(Eingabe!I59="","",Eingabe!I59) | BJ10: =IF(Eingabe!I59="","",Eingabe!I59*Eingabe!B59)
A11: =IF(Eingabe!A60="","",Eingabe!A60) | D11: =IF(Eingabe!B60="","",Eingabe!B60) | H11: =IF(Eingabe!C60="","",Eingabe!C60) | L11: =IF(Eingabe!D60="","",Eingabe!D60) | AH11: =IF(Eingabe!F60&Eingabe!G60="","",Eingabe!F60&" / "&Eingabe!G60) | BE11: =IF(Eingabe!I60="","",Eingabe!I60) | BJ11: =IF(Eingabe!I60="","",Eingabe!I60*Eingabe!B60)
A12: =IF(Eingabe!A61="","",Eingabe!A61) | D12: =IF(Eingabe!B61="","",Eingabe!B61) | H12: =IF(Eingabe!C61="","",Eingabe!C61) | L12: =IF(Eingabe!D61="","",Eingabe!D61) | AH12: =IF(Eingabe!F61&Eingabe!G61="","",Eingabe!F61&" / "&Eingabe!G61) | BE12: =IF(Eingabe!I61="","",Eingabe!I61) | BJ12: =IF(Eingabe!I61="","",Eingabe!I61*Eingabe!B61)
A13: =IF(Eingabe!A62="","",Eingabe!A62) | D13: =IF(Eingabe!B62="","",Eingabe!B62) | H13: =IF(Eingabe!C62="","",Eingabe!C62) | L13: =IF(Eingabe!D62="","",Eingabe!D62) | AH13: =IF(Eingabe!F62&Eingabe!G62="","",Eingabe!F62&" / "&Eingabe!G62) | BE13: =IF(Eingabe!I62="","",Eingabe!I62) | BJ13: =IF(Eingabe!I62="","",Eingabe!I62*Eingabe!B62)
A14: =IF(Eingabe!A63="","",Eingabe!A63) | D14: =IF(Eingabe!B63="","",Eingabe!B63) | H14: =IF(Eingabe!C63="","",Eingabe!C63) | L14: =IF(Eingabe!D63="","",Eingabe!D63) | AH14: =IF(Eingabe!F63&Eingabe!G63="","",Eingabe!F63&" / "&Eingabe!G63) | BE14: =IF(Eingabe!I63="","",Eingabe!I63) | BJ14: =IF(Eingabe!I63="","",Eingabe!I63*Eingabe!B63)
